[2024-03-30 22:42:56,986] INFO _log() L96   127.0.0.1 - - [30/Mar/2024 22:42:56] "GET /bops HTTP/1.1" 200 - - call_trace=/home/slsn/repos/bop_land_api/.venv/lib/python3.10/site-packages/werkzeug/_internal.py L96  
[2024-03-30 22:44:30,648] INFO _log() L96   127.0.0.1 - - [30/Mar/2024 22:44:30] "POST /login HTTP/1.1" 200 - - call_trace=/home/slsn/repos/bop_land_api/.venv/lib/python3.10/site-packages/werkzeug/_internal.py L96  
[2024-03-30 22:45:41,073] INFO _log() L96   127.0.0.1 - - [30/Mar/2024 22:45:41] "POST /login HTTP/1.1" 200 - - call_trace=/home/slsn/repos/bop_land_api/.venv/lib/python3.10/site-packages/werkzeug/_internal.py L96  
[2024-03-30 22:45:43,367] ERROR log_exception() L828  Exception on /secao [GET] - call_trace=/home/slsn/repos/bop_land_api/.venv/lib/python3.10/site-packages/flask/app.py L828 
Traceback (most recent call last):
  File "/home/slsn/repos/bop_land_api/.venv/lib/python3.10/site-packages/flask/app.py", line 1463, in wsgi_app
    response = self.full_dispatch_request()
  File "/home/slsn/repos/bop_land_api/.venv/lib/python3.10/site-packages/flask/app.py", line 872, in full_dispatch_request
    rv = self.handle_user_exception(e)
  File "/home/slsn/repos/bop_land_api/.venv/lib/python3.10/site-packages/flask_cors/extension.py", line 176, in wrapped_function
    return cors_after_request(app.make_response(f(*args, **kwargs)))
  File "/home/slsn/repos/bop_land_api/.venv/lib/python3.10/site-packages/flask/app.py", line 870, in full_dispatch_request
    rv = self.dispatch_request()
  File "/home/slsn/repos/bop_land_api/.venv/lib/python3.10/site-packages/flask/app.py", line 855, in dispatch_request
    return self.ensure_sync(self.view_functions[rule.endpoint])(**view_args)  # type: ignore[no-any-return]
  File "/home/slsn/repos/bop_land_api/.venv/lib/python3.10/site-packages/flask_openapi3/scaffold.py", line 117, in view_func
    response = func(**func_kwargs)
  File "/home/slsn/repos/bop_land_api/app.py", line 98, in get_dado_secao
    if session['email']:
  File "/home/slsn/repos/bop_land_api/.venv/lib/python3.10/site-packages/flask/sessions.py", line 84, in __getitem__
    return super().__getitem__(key)
KeyError: 'email'
[2024-03-30 22:45:43,369] INFO _log() L96   127.0.0.1 - - [30/Mar/2024 22:45:43] "[35m[1mGET /secao HTTP/1.1[0m" 500 - - call_trace=/home/slsn/repos/bop_land_api/.venv/lib/python3.10/site-packages/werkzeug/_internal.py L96  
[2024-03-30 22:46:10,845] INFO _log() L96   [31m[1mWARNING: This is a development server. Do not use it in a production deployment. Use a production WSGI server instead.[0m
 * Running on all addresses (0.0.0.0)
 * Running on http://127.0.0.1:5000
 * Running on http://172.24.235.173:5000 - call_trace=/home/slsn/repos/bop_land_api/.venv/lib/python3.10/site-packages/werkzeug/_internal.py L96  
[2024-03-30 22:46:10,845] INFO _log() L96   [33mPress CTRL+C to quit[0m - call_trace=/home/slsn/repos/bop_land_api/.venv/lib/python3.10/site-packages/werkzeug/_internal.py L96  
[2024-03-30 22:46:16,809] ERROR log_exception() L828  Exception on /secao [GET] - call_trace=/home/slsn/repos/bop_land_api/.venv/lib/python3.10/site-packages/flask/app.py L828 
Traceback (most recent call last):
  File "/home/slsn/repos/bop_land_api/.venv/lib/python3.10/site-packages/flask/app.py", line 1463, in wsgi_app
    response = self.full_dispatch_request()
  File "/home/slsn/repos/bop_land_api/.venv/lib/python3.10/site-packages/flask/app.py", line 872, in full_dispatch_request
    rv = self.handle_user_exception(e)
  File "/home/slsn/repos/bop_land_api/.venv/lib/python3.10/site-packages/flask_cors/extension.py", line 176, in wrapped_function
    return cors_after_request(app.make_response(f(*args, **kwargs)))
  File "/home/slsn/repos/bop_land_api/.venv/lib/python3.10/site-packages/flask/app.py", line 870, in full_dispatch_request
    rv = self.dispatch_request()
  File "/home/slsn/repos/bop_land_api/.venv/lib/python3.10/site-packages/flask/app.py", line 855, in dispatch_request
    return self.ensure_sync(self.view_functions[rule.endpoint])(**view_args)  # type: ignore[no-any-return]
  File "/home/slsn/repos/bop_land_api/.venv/lib/python3.10/site-packages/flask_openapi3/scaffold.py", line 117, in view_func
    response = func(**func_kwargs)
  File "/home/slsn/repos/bop_land_api/app.py", line 98, in get_dado_secao
    if session['email']:
  File "/home/slsn/repos/bop_land_api/.venv/lib/python3.10/site-packages/flask/sessions.py", line 84, in __getitem__
    return super().__getitem__(key)
KeyError: 'email'
[2024-03-30 22:46:16,810] INFO _log() L96   127.0.0.1 - - [30/Mar/2024 22:46:16] "[35m[1mGET /secao HTTP/1.1[0m" 500 - - call_trace=/home/slsn/repos/bop_land_api/.venv/lib/python3.10/site-packages/werkzeug/_internal.py L96  
[2024-03-30 22:46:48,605] INFO _log() L96   [31m[1mWARNING: This is a development server. Do not use it in a production deployment. Use a production WSGI server instead.[0m
 * Running on all addresses (0.0.0.0)
 * Running on http://127.0.0.1:5000
 * Running on http://172.24.235.173:5000 - call_trace=/home/slsn/repos/bop_land_api/.venv/lib/python3.10/site-packages/werkzeug/_internal.py L96  
[2024-03-30 22:46:48,605] INFO _log() L96   [33mPress CTRL+C to quit[0m - call_trace=/home/slsn/repos/bop_land_api/.venv/lib/python3.10/site-packages/werkzeug/_internal.py L96  
[2024-03-30 22:46:59,385] INFO _log() L96   127.0.0.1 - - [30/Mar/2024 22:46:59] "POST /login HTTP/1.1" 200 - - call_trace=/home/slsn/repos/bop_land_api/.venv/lib/python3.10/site-packages/werkzeug/_internal.py L96  
[2024-03-30 22:47:04,574] ERROR log_exception() L828  Exception on /secao [GET] - call_trace=/home/slsn/repos/bop_land_api/.venv/lib/python3.10/site-packages/flask/app.py L828 
Traceback (most recent call last):
  File "/home/slsn/repos/bop_land_api/.venv/lib/python3.10/site-packages/flask/app.py", line 1463, in wsgi_app
    response = self.full_dispatch_request()
  File "/home/slsn/repos/bop_land_api/.venv/lib/python3.10/site-packages/flask/app.py", line 872, in full_dispatch_request
    rv = self.handle_user_exception(e)
  File "/home/slsn/repos/bop_land_api/.venv/lib/python3.10/site-packages/flask_cors/extension.py", line 176, in wrapped_function
    return cors_after_request(app.make_response(f(*args, **kwargs)))
  File "/home/slsn/repos/bop_land_api/.venv/lib/python3.10/site-packages/flask/app.py", line 870, in full_dispatch_request
    rv = self.dispatch_request()
  File "/home/slsn/repos/bop_land_api/.venv/lib/python3.10/site-packages/flask/app.py", line 855, in dispatch_request
    return self.ensure_sync(self.view_functions[rule.endpoint])(**view_args)  # type: ignore[no-any-return]
  File "/home/slsn/repos/bop_land_api/.venv/lib/python3.10/site-packages/flask_openapi3/scaffold.py", line 117, in view_func
    response = func(**func_kwargs)
  File "/home/slsn/repos/bop_land_api/app.py", line 98, in get_dado_secao
    if session['email']:
  File "/home/slsn/repos/bop_land_api/.venv/lib/python3.10/site-packages/flask/sessions.py", line 84, in __getitem__
    return super().__getitem__(key)
KeyError: 'email'
[2024-03-30 22:47:04,575] INFO _log() L96   127.0.0.1 - - [30/Mar/2024 22:47:04] "[35m[1mGET /secao HTTP/1.1[0m" 500 - - call_trace=/home/slsn/repos/bop_land_api/.venv/lib/python3.10/site-packages/werkzeug/_internal.py L96  
[2024-03-30 23:04:26,695] INFO _log() L96   [31m[1mWARNING: This is a development server. Do not use it in a production deployment. Use a production WSGI server instead.[0m
 * Running on all addresses (0.0.0.0)
 * Running on http://127.0.0.1:5000
 * Running on http://172.24.235.173:5000 - call_trace=/home/slsn/repos/bop_land_api/.venv/lib/python3.10/site-packages/werkzeug/_internal.py L96  
[2024-03-30 23:04:26,695] INFO _log() L96   [33mPress CTRL+C to quit[0m - call_trace=/home/slsn/repos/bop_land_api/.venv/lib/python3.10/site-packages/werkzeug/_internal.py L96  
[2024-03-30 23:04:49,621] INFO _log() L96   127.0.0.1 - - [30/Mar/2024 23:04:49] "POST /login HTTP/1.1" 200 - - call_trace=/home/slsn/repos/bop_land_api/.venv/lib/python3.10/site-packages/werkzeug/_internal.py L96  
[2024-03-30 23:05:07,200] ERROR log_exception() L828  Exception on /secao [GET] - call_trace=/home/slsn/repos/bop_land_api/.venv/lib/python3.10/site-packages/flask/app.py L828 
Traceback (most recent call last):
  File "/home/slsn/repos/bop_land_api/.venv/lib/python3.10/site-packages/flask/app.py", line 1463, in wsgi_app
    response = self.full_dispatch_request()
  File "/home/slsn/repos/bop_land_api/.venv/lib/python3.10/site-packages/flask/app.py", line 873, in full_dispatch_request
    return self.finalize_request(rv)
  File "/home/slsn/repos/bop_land_api/.venv/lib/python3.10/site-packages/flask/app.py", line 892, in finalize_request
    response = self.make_response(rv)
  File "/home/slsn/repos/bop_land_api/.venv/lib/python3.10/site-packages/flask/app.py", line 1164, in make_response
    raise TypeError(
TypeError: The view function for 'get_dado_secao' did not return a valid response. The function either returned None or ended without a return statement.
[2024-03-30 23:05:07,202] INFO _log() L96   127.0.0.1 - - [30/Mar/2024 23:05:07] "[35m[1mGET /secao HTTP/1.1[0m" 500 - - call_trace=/home/slsn/repos/bop_land_api/.venv/lib/python3.10/site-packages/werkzeug/_internal.py L96  
[2024-03-30 23:17:09,033] INFO _log() L96   [31m[1mWARNING: This is a development server. Do not use it in a production deployment. Use a production WSGI server instead.[0m
 * Running on all addresses (0.0.0.0)
 * Running on http://127.0.0.1:5000
 * Running on http://172.24.235.173:5000 - call_trace=/home/slsn/repos/bop_land_api/.venv/lib/python3.10/site-packages/werkzeug/_internal.py L96  
[2024-03-30 23:17:09,033] INFO _log() L96   [33mPress CTRL+C to quit[0m - call_trace=/home/slsn/repos/bop_land_api/.venv/lib/python3.10/site-packages/werkzeug/_internal.py L96  
